<?xml version="1.0"?>
<sdf version="1.7">
    <world name="train_world">
        <physics name="1ms" type="ignored">
            <max_step_size>0.001</max_step_size>
            <real_time_factor>1.0</real_time_factor>
        </physics>
        <plugin
           filename="libignition-gazebo-physics-system.so"
           name="ignition::gazebo::systems::Physics">
       </plugin>
        <plugin
           filename="libignition-gazebo-user-commands-system.so"
           name="ignition::gazebo::systems::UserCommands">
       </plugin>
        <plugin
           filename="libignition-gazebo-scene-broadcaster-system.so"
           name="ignition::gazebo::systems::SceneBroadcaster">
       </plugin>
        <plugin
           filename="libignition-gazebo-imu-system.so"
           name="ignition::gazebo::systems::Imu">
       </plugin>
        <plugin filename="libignition-gazebo-contact-system.so"
       name="ignition::gazebo::systems::Contact">
       </plugin>
        <gui fullscreen="0">
            <!-- 3D scene -->
            <plugin filename="GzScene3D" name="3D View">
                <ignition-gui>
                    <title>3D View</title>
                    <property type="bool" key="showTitleBar">false</property>
                    <property type="string" key="state">docked</property>
                </ignition-gui>
                <engine>ogre2</engine>
                <scene>scene</scene>
                <ambient_light>0.4 0.4 0.4</ambient_light>
                <background_color>0.8 0.8 0.8</background_color>
            </plugin>
            <!-- World control -->
            <plugin filename="WorldControl" name="World control">
                <ignition-gui>
                    <title>World control</title>
                    <property type="bool" key="showTitleBar">false</property>
                    <property type="bool" key="resizable">false</property>
                    <property type="double" key="height">72</property>
                    <property type="double" key="width">121</property>
                    <property type="double" key="z">1</property>
                    <property type="string" key="state">floating</property>
                    <anchors target="3D View">
                        <line own="left" target="left"/>
                        <line own="bottom" target="bottom"/>
                    </anchors>
                </ignition-gui>
                <play_pause>true</play_pause>
                <step>true</step>
                <start_paused>true</start_paused>
                <service>/world/train_world/control</service>
                <stats_topic>/world/train_world/stats</stats_topic>
            </plugin>
            <!-- World statistics -->
            <plugin filename="WorldStats" name="World stats">
                <ignition-gui>
                    <title>World stats</title>
                    <property type="bool" key="showTitleBar">false</property>
                    <property type="bool" key="resizable">false</property>
                    <property type="double" key="height">110</property>
                    <property type="double" key="width">290</property>
                    <property type="double" key="z">1</property>
                    <property type="string" key="state">floating</property>
                    <anchors target="3D View">
                        <line own="right" target="right"/>
                        <line own="bottom" target="bottom"/>
                    </anchors>
                </ignition-gui>
                <sim_time>true</sim_time>
                <real_time>true</real_time>
                <real_time_factor>true</real_time_factor>
                <iterations>true</iterations>
                <topic>/world/train_world/stats</topic>
            </plugin>
            <!-- Entity tree -->
            <plugin filename="EntityTree" name="En6tity tree">
           </plugin>
            <!-- KeyPublisher plugin-->
            <plugin filename="KeyPublisher" name="Key Publisher"/>
        </gui>
        <light type="directional" name="sun">
            <cast_shadows>true</cast_shadows>
            <pose>0 0 10 0 0 0</pose>
            <diffuse>0.8 0.8 0.8 1</diffuse>
            <specular>0.2 0.2 0.2 1</specular>
            <attenuation>
                <range>1000</range>
                <constant>0.9</constant>
                <linear>0.01</linear>
                <quadratic>0.001</quadratic>
            </attenuation>
            <direction>-0.5 0.1 -0.9</direction>
        </light>
        <model name="ground_plane">
            <static>true</static>
            <link name="link">
                <collision name="collision">
                    <geometry>
                        <plane>
                            <normal>0 0 1</normal>
                        </plane>
                    </geometry>
                </collision>
                <visual name="visual">
                    <geometry>
                        <plane>
                            <normal>0 0 1</normal>
                            <size>100 100</size>
                        </plane>
                    </geometry>
                    <material>
                        <ambient>0.8 0.8 0.8 1</ambient>
                        <diffuse>0.8 0.8 0.8 1</diffuse>
                        <specular>0.8 0.8 0.8 1</specular>
                    </material>
                </visual>
            </link>
        </model>
        <model name='1' canonical_link='chassis'>
            <pose relative_to=world>2.1 0 0 0 0 0</pose>
            <frame name="lidar_frame" attached_to='chassis'>
                <pose>0.8 0 0.5 0 0 0</pose>
            </frame>
            <link name='chassis'>
                <pose relative_to='__model__'>0.5 0 0.4 0 0 0</pose>
                <inertial>
                    <!--inertial properties of the link mass, inertia matix-->
                    <mass>1.14395</mass>
                    <inertia>
                        <ixx>0.095329</ixx>
                        <ixy>0</ixy>
                        <ixz>0</ixz>
                        <iyy>0.381317</iyy>
                        <iyz>0</iyz>
                        <izz>0.476646</izz>
                    </inertia>
                </inertial>
                <visual name='visual'>
                    <geometry>
                        <box>
                            <size>2.0 1.0 0.5</size>
                        </box>
                    </geometry>
                    <!--let's add color to our link-->
                    <material>
                        <ambient>1.0 0.0 0.0 1</ambient>
                        <diffuse>0.5 0.0 0.0 1</diffuse>
                        <specular>1.0 0.0 0.0 1</specular>
                    </material>
                </visual>
                <collision name='collision'>
                    <geometry>
                        <box>
                            <size>2.0 1.0 0.5</size>
                        </box>
                    </geometry>
                </collision>
                <sensor name="imu_sensor" type="imu">
                    <always_on>1</always_on>
                    <update_rate>1</update_rate>
                    <visualize>true</visualize>
                    <topic>imu</topic>
                </sensor>
            </link>
            <link name='2'>
                <pose relative_to="chassis">-2.1 0 0 0 0 0</pose>
                <inertial>
                    <!--inertial properties of the link mass, inertia matix-->
                    <mass>1.14395</mass>
                    <inertia>
                        <ixx>0.095329</ixx>
                        <ixy>0</ixy>
                        <ixz>0</ixz>
                        <iyy>0.381317</iyy>
                        <iyz>0</iyz>
                        <izz>0.476646</izz>
                    </inertia>
                </inertial>
                <visual name='visual'>
                    <geometry>
                        <box>
                            <size>2.0 1.0 0.5</size>
                        </box>
                    </geometry>
                    <!--let's add color to our link-->
                    <material>
                        <ambient>0.0 0.0 0.2 1</ambient>
                        <diffuse>0.0 0.0 1.0 1</diffuse>
                        <specular>0.0 0.0 1.0 1</specular>
                    </material>
                </visual>
                <collision name='collision'>
                    <geometry>
                        <box>
                            <size>2.0 1.0 0.5</size>
                        </box>
                    </geometry>
                </collision>
            </link>
            <link name='3'>
                <pose relative_to="chassis">-4.2 0 0 0 0 0</pose>
                <inertial>
                    <!--inertial properties of the link mass, inertia matix-->
                    <mass>1.14395</mass>
                    <inertia>
                        <ixx>0.095329</ixx>
                        <ixy>0</ixy>
                        <ixz>0</ixz>
                        <iyy>0.381317</iyy>
                        <iyz>0</iyz>
                        <izz>0.476646</izz>
                    </inertia>
                </inertial>
                <visual name='visual'>
                    <geometry>
                        <box>
                            <size>2.0 1.0 0.5</size>
                        </box>
                    </geometry>
                    <!--let's add color to our link-->
                    <material>
                        <ambient>0.0 0.0 0.2 1</ambient>
                        <diffuse>0.0 0.0 1.0 1</diffuse>
                        <specular>0.0 0.0 1.0 1</specular>
                    </material>
                </visual>
                <collision name='collision'>
                    <geometry>
                        <box>
                            <size>2.0 1.0 0.5</size>
                        </box>
                    </geometry>
                </collision>
            </link>
            <link name='track_left'>
                <pose relative_to="chassis">2.18 0.6 -0.42 0 0 0</pose>
                <visual name='visual'>
                    <geometry>
                        <box>
                            <size>30.0 0.1 0.1</size>
                        </box>
                    </geometry>
                    <!--let's add color to our link-->
                    <material>
                        <ambient>0.0 0.0 0.0 1</ambient>
                        <diffuse>0.0 0.0 0.0 1</diffuse>
                        <specular>0.0 0.0 0.0 1</specular>
                    </material>
                </visual>
                <collision name='collision'>
                    <geometry>
                        <box>
                            <size>0.5 10.0 2.0</size>
                        </box>
                    </geometry>
                </collision>
            </link>
            <link name='track_right'>
                <pose relative_to="chassis">2.18 -0.6 -0.42 0 0 0</pose>
                <visual name='visual'>
                    <geometry>
                        <box>
                            <size>30.0 0.1 0.1</size>
                        </box>
                    </geometry>
                    <!--let's add color to our link-->
                    <material>
                        <ambient>0.0 0.0 0.0 1</ambient>
                        <diffuse>0.0 0.0 0.0 1</diffuse>
                        <specular>0.0 0.0 0.0 1</specular>
                    </material>
                </visual>
                <collision name='collision'>
                    <geometry>
                        <box>
                            <size>0.5 10.0 2.0</size>
                        </box>
                    </geometry>
                </collision>
            </link>
            <link name='road'>
                <pose relative_to="chassis">5.5 0 -0.4 0 0 0</pose>
                <visual name='visual'>
                    <geometry>
                        <box>
                            <size>4.0 20.0 0.02</size>
                        </box>
                    </geometry>
                    <!--let's add color to our link-->
                    <material>
                        <ambient>0.0 0.0 0.0 1</ambient>
                        <diffuse>0.0 0.0 0.0 1</diffuse>
                        <specular>0.0 0.0 0.0 1</specular>
                    </material>
                </visual>
                <collision name='collision'>
                    <geometry>
                        <box>
                            <size>2.0 5.0 2.0</size>
                        </box>
                    </geometry>
                </collision>
            </link>
            <joint name='1_2_joint' type='fixed'>
                <pose relative_to='2'/>
                <parent>chassis</parent>
                <child>2</child>
            </joint>
            <joint name='2_3_joint' type='fixed'>
                <pose relative_to='3'/>
                <parent>2</parent>
                <child>3</child>
            </joint>
            <!--Left wheel-->
            <link name='left_wheel_1'>
                <pose relative_to="chassis">0 0.6 0 -1.5707 0 0</pose>
                <!--angles are in radian-->
                <inertial>
                    <mass>1</mass>
                    <inertia>
                        <ixx>0.043333</ixx>
                        <ixy>0</ixy>
                        <ixz>0</ixz>
                        <iyy>0.043333</iyy>
                        <iyz>0</iyz>
                        <izz>0.08</izz>
                    </inertia>
                </inertial>
                <visual name='visual'>
                    <geometry>
                        <cylinder>
                            <radius>0.4</radius>
                            <length>0.1</length>
                        </cylinder>
                    </geometry>
                    <material>
                        <ambient>0.0 0.0 0.0 1</ambient>
                        <diffuse>0.0 0.0 0.0 1</diffuse>
                        <specular>0.0 0.0 0.0 1</specular>
                    </material>
                </visual>
                <collision name='collision'>
                    <geometry>
                        <cylinder>
                            <radius>0.4</radius>
                            <length>0.1</length>
                        </cylinder>
                    </geometry>
                </collision>
            </link>
            <!--The same as left wheel but with different position-->
            <link name='right_wheel_1'>
                <pose relative_to="chassis">0 -0.6 0 -1.5707 0 0</pose>
                <!--angles are in radian-->
                <inertial>
                    <mass>1</mass>
                    <inertia>
                        <ixx>0.043333</ixx>
                        <ixy>0</ixy>
                        <ixz>0</ixz>
                        <iyy>0.043333</iyy>
                        <iyz>0</iyz>
                        <izz>0.08</izz>
                    </inertia>
                </inertial>
                <visual name='visual'>
                    <geometry>
                        <cylinder>
                            <radius>0.4</radius>
                            <length>0.1</length>
                        </cylinder>
                    </geometry>
                    <material>
                        <ambient>0.0 0.0 0.0 1</ambient>
                        <diffuse>0.0 0.0 0.0 1</diffuse>
                        <specular>0.0 0.0 0.0 1</specular>
                    </material>
                </visual>
                <collision name='collision'>
                    <geometry>
                        <cylinder>
                            <radius>0.4</radius>
                            <length>0.1</length>
                        </cylinder>
                    </geometry>
                </collision>
            </link>
            <!--left wheel joint-->
            <joint name='left_wheel_joint_1' type='revolute'>
                <pose relative_to='left_wheel_1'/>
                <parent>chassis</parent>
                <child>left_wheel_1</child>
                <axis>
                    <xyz expressed_in='__model__'>0 1 0</xyz>
                    <!--can be descired to any frame or even arbitrary frames-->
                    <limit>
                        <lower>-1.79769e+308</lower>
                        <!--negative infinity-->
                        <upper>1.79769e+308</upper>
                        <!--positive infinity-->
                    </limit>
                </axis>
            </joint>
            <!--right wheel joint-->
            <joint name='right_wheel_joint_1' type='revolute'>
                <pose relative_to='right_wheel_1'/>
                <parent>chassis</parent>
                <child>right_wheel_1</child>
                <axis>
                    <xyz expressed_in='__model__'>0 1 0</xyz>
                    <limit>
                        <lower>-1.79769e+308</lower>
                        <!--negative infinity-->
                        <upper>1.79769e+308</upper>
                        <!--positive infinity-->
                    </limit>
                </axis>
            </joint>
            <plugin
               filename="libignition-gazebo-diff-drive-system.so"
               name="ignition::gazebo::systems::DiffDrive">
                <left_joint>left_wheel_joint_1</left_joint>
                <right_joint>right_wheel_joint_1</right_joint>
                <wheel_separation>1.2</wheel_separation>
                <wheel_radius>0.4</wheel_radius>
                <odom_publish_frequency>1</odom_publish_frequency>
                <topic>cmd_vel</topic>
            </plugin>
            <!--Left wheel-->
            <link name='left_wheel_2'>
                <pose relative_to="chassis">-2.1 0.6 0 -1.5707 0 0</pose>
                <!--angles are in radian-->
                <inertial>
                    <mass>1</mass>
                    <inertia>
                        <ixx>0.043333</ixx>
                        <ixy>0</ixy>
                        <ixz>0</ixz>
                        <iyy>0.043333</iyy>
                        <iyz>0</iyz>
                        <izz>0.08</izz>
                    </inertia>
                </inertial>
                <visual name='visual'>
                    <geometry>
                        <cylinder>
                            <radius>0.4</radius>
                            <length>0.1</length>
                        </cylinder>
                    </geometry>
                    <material>
                        <ambient>0.0 0.0 0.0 1</ambient>
                        <diffuse>0.0 0.0 0.0 1</diffuse>
                        <specular>0.0 0.0 0.0 1</specular>
                    </material>
                </visual>
                <collision name='collision'>
                    <geometry>
                        <cylinder>
                            <radius>0.4</radius>
                            <length>0.1</length>
                        </cylinder>
                    </geometry>
                </collision>
            </link>
            <!--The same as left wheel but with different position-->
            <link name='right_wheel_2'>
                <pose relative_to="chassis">-2.1 -0.6 0 -1.5707 0 0</pose>
                <!--angles are in radian-->
                <inertial>
                    <mass>1</mass>
                    <inertia>
                        <ixx>0.043333</ixx>
                        <ixy>0</ixy>
                        <ixz>0</ixz>
                        <iyy>0.043333</iyy>
                        <iyz>0</iyz>
                        <izz>0.08</izz>
                    </inertia>
                </inertial>
                <visual name='visual'>
                    <geometry>
                        <cylinder>
                            <radius>0.4</radius>
                            <length>0.1</length>
                        </cylinder>
                    </geometry>
                    <material>
                        <ambient>0.0 0.0 0.0 1</ambient>
                        <diffuse>0.0 0.0 0.0 1</diffuse>
                        <specular>0.0 0.0 0.0 1</specular>
                    </material>
                </visual>
                <collision name='collision'>
                    <geometry>
                        <cylinder>
                            <radius>0.4</radius>
                            <length>0.1</length>
                        </cylinder>
                    </geometry>
                </collision>
            </link>
            <!--left wheel joint-->
            <joint name='left_wheel_joint_2' type='revolute'>
                <pose relative_to='left_wheel_2'/>
                <parent>2</parent>
                <child>left_wheel_2</child>
                <axis>
                    <xyz expressed_in='__model__'>0 1 0</xyz>
                    <!--can be descired to any frame or even arbitrary frames-->
                    <limit>
                        <lower>-1.79769e+308</lower>
                        <!--negative infinity-->
                        <upper>1.79769e+308</upper>
                        <!--positive infinity-->
                    </limit>
                </axis>
            </joint>
            <!--right wheel joint-->
            <joint name='right_wheel_joint_2' type='revolute'>
                <pose relative_to='right_wheel_2'/>
                <parent>2</parent>
                <child>right_wheel_2</child>
                <axis>
                    <xyz expressed_in='__model__'>0 1 0</xyz>
                    <limit>
                        <lower>-1.79769e+308</lower>
                        <!--negative infinity-->
                        <upper>1.79769e+308</upper>
                        <!--positive infinity-->
                    </limit>
                </axis>
            </joint>
            <!--Left wheel-->
            <link name='left_wheel_3'>
                <pose relative_to="chassis">-4.2 0.6 0 -1.5707 0 0</pose>
                <!--angles are in radian-->
                <inertial>
                    <mass>1</mass>
                    <inertia>
                        <ixx>0.043333</ixx>
                        <ixy>0</ixy>
                        <ixz>0</ixz>
                        <iyy>0.043333</iyy>
                        <iyz>0</iyz>
                        <izz>0.08</izz>
                    </inertia>
                </inertial>
                <visual name='visual'>
                    <geometry>
                        <cylinder>
                            <radius>0.4</radius>
                            <length>0.1</length>
                        </cylinder>
                    </geometry>
                    <material>
                        <ambient>0.0 0.0 0.0 1</ambient>
                        <diffuse>0.0 0.0 0.0 1</diffuse>
                        <specular>0.0 0.0 0.0 1</specular>
                    </material>
                </visual>
                <collision name='collision'>
                    <geometry>
                        <cylinder>
                            <radius>0.4</radius>
                            <length>0.1</length>
                        </cylinder>
                    </geometry>
                </collision>
            </link>
            <!--The same as left wheel but with different position-->
            <link name='right_wheel_3'>
                <pose relative_to="chassis">-4.2 -0.6 0 -1.5707 0 0</pose>
                <!--angles are in radian-->
                <inertial>
                    <mass>1</mass>
                    <inertia>
                        <ixx>0.043333</ixx>
                        <ixy>0</ixy>
                        <ixz>0</ixz>
                        <iyy>0.043333</iyy>
                        <iyz>0</iyz>
                        <izz>0.08</izz>
                    </inertia>
                </inertial>
                <visual name='visual'>
                    <geometry>
                        <cylinder>
                            <radius>0.4</radius>
                            <length>0.1</length>
                        </cylinder>
                    </geometry>
                    <material>
                        <ambient>0.0 0.0 0.0 1</ambient>
                        <diffuse>0.0 0.0 0.0 1</diffuse>
                        <specular>0.0 0.0 0.0 1</specular>
                    </material>
                </visual>
                <collision name='collision'>
                    <geometry>
                        <cylinder>
                            <radius>0.4</radius>
                            <length>0.1</length>
                        </cylinder>
                    </geometry>
                </collision>
            </link>
            <!--left wheel joint-->
            <joint name='left_wheel_joint_3' type='revolute'>
                <pose relative_to='left_wheel_3'/>
                <parent>3</parent>
                <child>left_wheel_3</child>
                <axis>
                    <xyz expressed_in='__model__'>0 1 0</xyz>
                    <!--can be descired to any frame or even arbitrary frames-->
                    <limit>
                        <lower>-1.79769e+308</lower>
                        <!--negative infinity-->
                        <upper>1.79769e+308</upper>
                        <!--positive infinity-->
                    </limit>
                </axis>
            </joint>
            <!--right wheel joint-->
            <joint name='right_wheel_joint_3' type='revolute'>
                <pose relative_to='right_wheel_3'/>
                <parent>3</parent>
                <child>right_wheel_3</child>
                <axis>
                    <xyz expressed_in='__model__'>0 1 0</xyz>
                    <limit>
                        <lower>-1.79769e+308</lower>
                        <!--negative infinity-->
                        <upper>1.79769e+308</upper>
                        <!--positive infinity-->
                    </limit>
                </axis>
            </joint>
        </model>
        <model name='obstacle_1'>
            <static>true</static>
            <pose>18 0 0.25 0 0 0</pose>
            <!--pose relative to the world-->
            <link name='obstacle_1'>
                <pose/>
                <visual name='visual'>
                    <geometry>
                        <box>
                            <size>0.5 0.5 0.5</size>
                        </box>
                    </geometry>
                    <!--let's add color to our link-->
                    <material>
                        <ambient>0.0 1.0 0.0 1</ambient>
                        <diffuse>0.0 1.0 0.0 1</diffuse>
                        <specular>0.0 1.0 0.0 1</specular>
                    </material>
                </visual>
                <collision name='collision'>
                    <geometry>
                        <box>
                            <size>2.0 5.0 2.0</size>
                        </box>
                    </geometry>
                </collision>
            </link>
            <plugin filename="libignition-gazebo-touchplugin-system.so"
                name="ignition::gazebo::systems::TouchPlugin">
                <target>1</target>
                <namespace>obstacle_1</namespace>
                <time>0.001</time>
                <enabled>true</enabled>
            </plugin>
            <plugin filename="libignition-gazebo-triggered-publisher-system.so"
            name="ignition::gazebo::systems::TriggeredPublisher">
                <input type="ignition.msgs.Boolean" topic="/obstacle_1/touched">
                    <match>data: true</match>
                </input>
                <output type="ignition.msgs.Twist" topic="/cmd_vel">
            linear: {x: 0.0}, angular: {z: 0.0}
            </output>
            </plugin>
        </model>
        <model name='box'>
            <static>true</static>
            <pose>8.0 0 0 0 0</pose>
            <!--pose relative to the world-->
            <link name='box'>
                <pose/>
                <visual name='visual'>
                    <geometry>
                        <box>
                            <size>3.0 4.0 0.02</size>
                        </box>
                    </geometry>
                    <!--let's add color to our link-->
                    <material>
                        <ambient>0.0 0.0 0.0 1</ambient>
                        <diffuse>0.0 0.0 0.0 1</diffuse>
                        <specular>0.0 0.0 0.0 1</specular>
                    </material>
                </visual>
                <collision name='collision'>
                    <geometry>
                        <box>
                            <size>4.0 5.0 2.0</size>
                        </box>
                    </geometry>
                </collision>
            </link>
            <plugin filename="libignition-gazebo-touchplugin-system.so"
                name="ignition::gazebo::systems::TouchPlugin">
                <target>1</target>
                <namespace>obstacle_1</namespace>
                <time>0.001</time>
                <enabled>true</enabled>
            </plugin>
            <plugin filename="libignition-gazebo-triggered-publisher-system.so"
            name="ignition::gazebo::systems::TriggeredPublisher">
                <input type="ignition.msgs.Boolean" topic="/obstacle_1/touched">
                    <match>data: true</match>
                </input>
                <output type="ignition.msgs.Twist" topic="/cmd_vel">
            linear: {x: 0.0}, angular: {z: 0.0}
            </output>
            </plugin>
        </model>
        <actor name="human_1">
            <skin>
                <filename>./walk.dae</filename>
                <scale>0.1</scale>
            </skin>
            <animation name="walk">
                <filename>./walk.dae</filename>
            </animation>
            <script>
                <loop>true</loop>
                <delay_start>0.000000</delay_start>
                <auto_start>true</auto_start>
                <trajectory id="0" type="walk">
                    <waypoint>
                        <time>0</time>
                        <pose>7 10.0 1.0 0 0 -1.57</pose>
                    </waypoint>
                    <waypoint>
                        <time>2</time>
                        <pose>7 8.0 1.0 0 0 -1.57</pose>
                    </waypoint>
                    <waypoint>
                        <time>4</time>
                        <pose>7 6.0 1.0 0 0 -1.57</pose>
                    </waypoint>
                    <waypoint>
                        <time>6</time>
                        <pose>7 4.0 1.0 0 0 -1.57</pose>
                    </waypoint>
                    <waypoint>
                        <time>8</time>
                        <pose>7 2.0 1.0 0 0 -1.57</pose>
                    </waypoint>
                    <waypoint>
                        <time>10</time>
                        <pose>7 0.0 1.0 0 0 -1.57</pose>
                    </waypoint>
                    <waypoint>
                        <time>12</time>
                        <pose>7 -2.0 1.0 0 0 -1.57</pose>
                    </waypoint>
                    <waypoint>
                        <time>16</time>
                        <pose>7 -4.0 1.0 0 0 -1.57</pose>
                    </waypoint>
                    <waypoint>
                        <time>18</time>
                        <pose>7 -6.0 1.0 0 0 -1.57</pose>
                    </waypoint>
                    <waypoint>
                        <time>20</time>
                        <pose>7 -8.0 1.0 0 0 -1.57</pose>
                    </waypoint>
                    <waypoint>
                        <time>22</time>
                        <pose>7 -10.0 1.0 0 0 -1.57</pose>
                    </waypoint>
                    <waypoint>
                        <time>24</time>
                        <pose>7 -12.0 1.0 0 0 -1.57</pose>
                    </waypoint>
                </trajectory>
            </script>
            <sensor name="imu_sensor" type="imu">
                <always_on>1</always_on>
                <update_rate>1</update_rate>
                <visualize>true</visualize>
                <topic>imu</topic>
            </sensor>
        </actor>
        <actor name="human_2">
            <skin>
                <filename>./walk.dae</filename>
                <scale>0.1</scale>
            </skin>
            <animation name="walk">
                <filename>./walk.dae</filename>
            </animation>
        <script>
            <loop>true</loop>
            <delay_start>0.000000</delay_start>
            <auto_start>true</auto_start>
            <trajectory id="0" type="walk">
                <waypoint>
                    <time>0</time>
                    <pose>9 10.0 1.0 0 0 -1.57</pose>
                </waypoint>
                <waypoint>
                    <time>2</time>
                    <pose>9 8.0 1.0 0 0 -1.57</pose>
                </waypoint>
                <waypoint>
                    <time>4</time>
                    <pose>9 6.0 1.0 0 0 -1.57</pose>
                </waypoint>
                <waypoint>
                    <time>6</time>
                    <pose>9 4.0 1.0 0 0 -1.57</pose>
                </waypoint>
                <waypoint>
                    <time>8</time>
                    <pose>9 3.0 1.0 0 0 -1.57</pose>
                </waypoint>
                <waypoint>
                    <time>10</time>
                    <pose>9 3.0 1.0 0 0 -1.57</pose>
                </waypoint>
                <waypoint>
                    <time>12</time>
                    <pose>9 3.0 1.0 0 0 -1.57</pose>
                </waypoint>
                <waypoint>
                    <time>16</time>
                    <pose>9 3.0 1.0 0 0 -1.57</pose>
                </waypoint>
                <waypoint>
                    <time>18</time>
                    <pose>9 3.0 1.0 0 0 -1.57</pose>
                </waypoint>
                <waypoint>
                    <time>20</time>
                    <pose>9 2.0 1.0 0 0 -1.57</pose>
                </waypoint>
                <waypoint>
                    <time>22</time>
                    <pose>9 2.0 1.0 0 0 -1.57</pose>
                </waypoint>
                <waypoint>
                    <time>24</time>
                    <pose>9 2.0 1.0 0 0 -1.57</pose>
                </waypoint>
                <waypoint>
                    <time>26</time>
                    <pose>9 2.0 1.0 0 0 -1.57</pose>
                </waypoint>
                <waypoint>
                    <time>28</time>
                    <pose>9 2.0 1.0 0 0 -1.57</pose>
                </waypoint>
                <waypoint>
                    <time>30</time>
                    <pose>9 0.0 1.0 0 0 -1.57</pose>
                </waypoint>
                <waypoint>
                    <time>32</time>
                    <pose>9 0.0 1.0 0 0 -1.57</pose>
                </waypoint>
                <waypoint>
                    <time>34</time>
                    <pose>9 -3.0 1.0 0 0 -1.57</pose>
                </waypoint>
                <waypoint>
                    <time>36</time>
                    <pose>9 -5.0 1.0 0 0 -1.57</pose>
                </waypoint>
            </trajectory>
        </script>
        <sensor name="imu_sensor" type="imu">
            <always_on>1</always_on>
            <update_rate>1</update_rate>
            <visualize>true</visualize>
            <topic>imu</topic>
        </sensor>
    </actor>
    <!-- Moving Forward-->
    <plugin filename="libignition-gazebo-triggered-publisher-system.so"
            name="ignition::gazebo::systems::TriggeredPublisher">
        <input type="ignition.msgs.Int32" topic="/keyboard/keypress">
            <match field="data">16777235</match>
        </input>
        <output type="ignition.msgs.Twist" topic="/cmd_vel">
       linear: {x: 0.6}, angular: {z: 0.0}
        </output>
    </plugin>
    <!-- Moving Backward-->
    <plugin filename="libignition-gazebo-triggered-publisher-system.so"
       name="ignition::gazebo::systems::TriggeredPublisher">
        <input type="ignition.msgs.Int32" topic="/keyboard/keypress">
            <match field="data">16777237</match>
        </input>
        <output type="ignition.msgs.Twist" topic="/cmd_vel">
       linear: {x: -0.5}, angular: {z: 0.0}
      </output>
    </plugin>
    <!-- Moving Right-->
    <plugin filename="libignition-gazebo-triggered-publisher-system.so"
       name="ignition::gazebo::systems::TriggeredPublisher">
        <input type="ignition.msgs.Int32" topic="/keyboard/keypress">
            <match field="data">16777236</match>
        </input>
        <output type="ignition.msgs.Twist" topic="/cmd_vel">
       linear: {x: 0.0}, angular: {z: 0.5}
      </output>
    </plugin>
    <!-- Moving Left-->
    <plugin filename="libignition-gazebo-triggered-publisher-system.so"
            name="ignition::gazebo::systems::TriggeredPublisher">
        <input type="ignition.msgs.Int32" topic="/keyboard/keypress">
            <match field="data">16777234</match>
        </input>
        <output type="ignition.msgs.Twist" topic="/cmd_vel">
             linear: {x: 0.0}, angular: {z: -0.5}
            </output>
    </plugin>
    <plugin filename="libignition-gazebo-triggered-publisher-system.so"
            name="ignition::gazebo::systems::TriggeredPublisher">
        <input type="ignition.msgs.Boolean" topic="/obstacle_1/touched">
            <match>data: true</match>
        </input>
        <output type="ignition.msgs.Twist" topic="/cmd_vel">
            linear: {x: 0.0}, angular: {z: 0.0}
       </output>
    </plugin>
    <plugin filename="libignition-gazebo-triggered-publisher-system.so"
                name="ignition::gazebo::systems::TriggeredPublisher">
        <input type="ignition.msgs.Boolean" topic="/naman/touched">
            <match>data: true</match>
        </input>
        <output type="ignition.msgs.Twist" topic="/cmd_vel">
                linear: {x: 0.0}, angular: {z: 0.0}
                </output>
        <sensor name="imu_sensor" type="imu">
            <always_on>1</always_on>
            <update_rate>1</update_rate>
            <visualize>true</visualize>
            <topic>imu</topic>
        </sensor>
    </plugin>
</world>
</sdf>